Workbook
Name DocList: List[文档编码]

Sheet List
B1: Technical Document Master List 技术文件清单 | C1: 文件总数 | D1: =COUNTA(List[文档编码]) -> 47 | E1: 工令号 | F1: 24001A | G1: 文件目录 | H1: =HYPERLINK(".",".\") -> .\
C2: 已受控数 | D2: =COUNT(List[首版受控]) -> 0 | E2: 最近更新 | F2: =MAX(List[末版受控]) -> 0 | G2: 日志目录 | H2: =HYPERLINK(H1&"!log\") -> .\!log\
I3: 分发
A4: 文档编码 | B4: 文档标题 | C4: 版本 | D4: 首版受控 | E4: 末版受控 | F4: 作者 | G4: 备注 | H4: 链接 | I4: MKT | J4: PUR | K4: PDE | L4: PMD | M4: TQM
B5: 基础设计 | C5: =IFERROR(VLOOKUP(List[[#This Row],[末版受控]]&List[[#This Row],[文档编码]],Log[],MATCH(Log[[#Headers],[版本]],Log[#Headers],0),0),"") -> 0 | D5: {=IF(IFERROR(MATCH(List[[#This Row],[文档编码]],Log[文档编码],0),0),MIN(IF(Log[文档编码]=List[[#This Row],[文档编码]],Log[日期])),"")} | E5: {=IF(IFERROR(MATCH(List[[#This Row],[文档编码]],Log[文档编码],0),FALSE),MAX(IF(Log[文档编码]=List[[#This Row],[文档编码]],Log[日期])),"")} | G5: 商务阶段发放 | H5: =HYPERLINK($H$1&List[[#This Row],[文档编码]]) -> .\
A6: =$F$1&"-TE-SP-0001" -> 24001A-TE-SP-0001 | B6: 技术规格书 | C6: =IFERROR(VLOOKUP(List[[#This Row],[末版受控]]&List[[#This Row],[文档编码]],Log[],MATCH(Log[[#Headers],[版本]],Log[#Headers],0),0),"") | D6: {=IF(IFERROR(MATCH(List[[#This Row],[文档编码]],Log[文档编码],0),0),MIN(IF(Log[文档编码]=List[[#This Row],[文档编码]],Log[日期])),"")} | E6: {=IF(IFERROR(MATCH(List[[#This Row],[文档编码]],Log[文档编码],0),FALSE),MAX(IF(Log[文档编码]=List[[#This Row],[文档编码]],Log[日期])),"")} | G6: 参考标准, 各专业的施工工艺, 工作界面, 设备清单 | H6: =HYPERLINK($H$1&List[[#This Row],[文档编码]]) -> .\24001A-TE-SP-0001
A7: =$F$1&"-TE-DW-0001" -> 24001A-TE-DW-0001 | B7: 产品总图 | C7: =IFERROR(VLOOKUP(List[[#This Row],[末版受控]]&List[[#This Row],[文档编码]],Log[],MATCH(Log[[#Headers],[版本]],Log[#Headers],0),0),"") | D7: {=IF(IFERROR(MATCH(List[[#This Row],[文档编码]],Log[文档编码],0),0),MIN(IF(Log[文档编码]=List[[#This Row],[文档编码]],Log[日期])),"")} | E7: {=IF(IFERROR(MATCH(List[[#This Row],[文档编码]],Log[文档编码],0),FALSE),MAX(IF(Log[文档编码]=List[[#This Row],[文档编码]],Log[日期])),"")} | G7: 包含尺寸 / 主要设备布置 / 开口等信息, 用于商务确认. | H7: =HYPERLINK($H$1&List[[#This Row],[文档编码]]) -> .\24001A-TE-DW-0001
B8: 箱体生产设计 | C8: =IFERROR(VLOOKUP(List[[#This Row],[末版受控]]&List[[#This Row],[文档编码]],Log[],MATCH(Log[[#Headers],[版本]],Log[#Headers],0),0),"") -> 0 | D8: {=IF(IFERROR(MATCH(List[[#This Row],[文档编码]],Log[文档编码],0),0),MIN(IF(Log[文档编码]=List[[#This Row],[文档编码]],Log[日期])),"")} | E8: {=IF(IFERROR(MATCH(List[[#This Row],[文档编码]],Log[文档编码],0),FALSE),MAX(IF(Log[文档编码]=List[[#This Row],[文档编码]],Log[日期])),"")} | H8: =HYPERLINK($H$1&List[[#This Row],[文档编码]]) -> .\
A9: =$F$1&"-ST-CA-0001" -> 24001A-ST-CA-0001 | B9: 结构强度计算书 | C9: =IFERROR(VLOOKUP(List[[#This Row],[末版受控]]&List[[#This Row],[文档编码]],Log[],MATCH(Log[[#Headers],[版本]],Log[#Headers],0),0),"") | D9: {=IF(IFERROR(MATCH(List[[#This Row],[文档编码]],Log[文档编码],0),0),MIN(IF(Log[文档编码]=List[[#This Row],[文档编码]],Log[日期])),"")} | E9: {=IF(IFERROR(MATCH(List[[#This Row],[文档编码]],Log[文档编码],0),FALSE),MAX(IF(Log[文档编码]=List[[#This Row],[文档编码]],Log[日期])),"")} | H9: =HYPERLINK($H$1&List[[#This Row],[文档编码]]) -> .\24001A-ST-CA-0001
A10: =$F$1&"-ST-DW-0001" -> 24001A-ST-DW-0001 | B10: 结构总图 | C10: =IFERROR(VLOOKUP(List[[#This Row],[末版受控]]&List[[#This Row],[文档编码]],Log[],MATCH(Log[[#Headers],[版本]],Log[#Headers],0),0),"") | D10: {=IF(IFERROR(MATCH(List[[#This Row],[文档编码]],Log[文档编码],0),0),MIN(IF(Log[文档编码]=List[[#This Row],[文档编码]],Log[日期])),"")} | E10: {=IF(IFERROR(MATCH(List[[#This Row],[文档编码]],Log[文档编码],0),FALSE),MAX(IF(Log[文档编码]=List[[#This Row],[文档编码]],Log[日期])),"")} | G10: 含工令下所有结构件组装信息。如果工令只有箱体的话，该图相当于箱体总图 | H10: =HYPERLINK($H$1&List[[#This Row],[文档编码]]) -> .\24001A-ST-DW-0001
A11: =$F$1&"-ST-DW-0008" -> 24001A-ST-DW-0008 | B11: 结构标贴图 | C11: =IFERROR(VLOOKUP(List[[#This Row],[末版受控]]&List[[#This Row],[文档编码]],Log[],MATCH(Log[[#Headers],[版本]],Log[#Headers],0),0),"") | D11: {=IF(IFERROR(MATCH(List[[#This Row],[文档编码]],Log[文档编码],0),0),MIN(IF(Log[文档编码]=List[[#This Row],[文档编码]],Log[日期])),"")} | E11: {=IF(IFERROR(MATCH(List[[#This Row],[文档编码]],Log[文档编码],0),FALSE),MAX(IF(Log[文档编码]=List[[#This Row],[文档编码]],Log[日期])),"")} | G11: 包含尺寸 / 主要设备布置 / 开口等信息, 用于商务确认. | H11: =HYPERLINK($H$1&List[[#This Row],[文档编码]]) -> .\24001A-ST-DW-0008
A12: =$F$1&"-ST-DW-0100" -> 24001A-ST-DW-0100 | B12: 箱体 - 总图 | C12: =IFERROR(VLOOKUP(List[[#This Row],[末版受控]]&List[[#This Row],[文档编码]],Log[],MATCH(Log[[#Headers],[版本]],Log[#Headers],0),0),"") | D12: {=IF(IFERROR(MATCH(List[[#This Row],[文档编码]],Log[文档编码],0),0),MIN(IF(Log[文档编码]=List[[#This Row],[文档编码]],Log[日期])),"")} | E12: {=IF(IFERROR(MATCH(List[[#This Row],[文档编码]],Log[文档编码],0),FALSE),MAX(IF(Log[文档编码]=List[[#This Row],[文档编码]],Log[日期])),"")} | G12: 箱体总图 | H12: =HYPERLINK($H$1&List[[#This Row],[文档编码]]) -> .\24001A-ST-DW-0100
A13: =$F$1&"-ST-DW-0110" -> 24001A-ST-DW-0110 | B13: 箱体 - 顶面装配图 | C13: =IFERROR(VLOOKUP(List[[#This Row],[末版受控]]&List[[#This Row],[文档编码]],Log[],MATCH(Log[[#Headers],[版本]],Log[#Headers],0),0),"") | D13: {=IF(IFERROR(MATCH(List[[#This Row],[文档编码]],Log[文档编码],0),0),MIN(IF(Log[文档编码]=List[[#This Row],[文档编码]],Log[日期])),"")} | E13: {=IF(IFERROR(MATCH(List[[#This Row],[文档编码]],Log[文档编码],0),FALSE),MAX(IF(Log[文档编码]=List[[#This Row],[文档编码]],Log[日期])),"")} | G13: 顶部框架 / 顶横梁分布 / 开孔 / 吊点 | H13: =HYPERLINK($H$1&List[[#This Row],[文档编码]]) -> .\24001A-ST-DW-0110
A14: =$F$1&"-ST-DW-0120" -> 24001A-ST-DW-0120 | B14: 箱体 - 底架装配图 | C14: =IFERROR(VLOOKUP(List[[#This Row],[末版受控]]&List[[#This Row],[文档编码]],Log[],MATCH(Log[[#Headers],[版本]],Log[#Headers],0),0),"") | D14: {=IF(IFERROR(MATCH(List[[#This Row],[文档编码]],Log[文档编码],0),0),MIN(IF(Log[文档编码]=List[[#This Row],[文档编码]],Log[日期])),"")} | E14: {=IF(IFERROR(MATCH(List[[#This Row],[文档编码]],Log[文档编码],0),FALSE),MAX(IF(Log[文档编码]=List[[#This Row],[文档编码]],Log[日期])),"")} | G14: 底架框架 / 底横梁分布 / 开孔 / 吊点/ 抬高底座 | H14: =HYPERLINK($H$1&List[[#This Row],[文档编码]]) -> .\24001A-ST-DW-0120
A15: =$F$1&"-ST-DW-0130" -> 24001A-ST-DW-0130 | B15: 箱体 - 左侧装配图 | C15: =IFERROR(VLOOKUP(List[[#This Row],[末版受控]]&List[[#This Row],[文档编码]],Log[],MATCH(Log[[#Headers],[版本]],Log[#Headers],0),0),"") | D15: {=IF(IFERROR(MATCH(List[[#This Row],[文档编码]],Log[文档编码],0),0),MIN(IF(Log[文档编码]=List[[#This Row],[文档编码]],Log[日期])),"")} | E15: {=IF(IFERROR(MATCH(List[[#This Row],[文档编码]],Log[文档编码],0),FALSE),MAX(IF(Log[文档编码]=List[[#This Row],[文档编码]],Log[日期])),"")} | G15: 侧面开孔尺寸 / 位置 | H15: =HYPERLINK($H$1&List[[#This Row],[文档编码]]) -> .\24001A-ST-DW-0130
A16: =$F$1&"-ST-DW-0140" -> 24001A-ST-DW-0140 | B16: 箱体 - 右侧装配图 | C16: =IFERROR(VLOOKUP(List[[#This Row],[末版受控]]&List[[#This Row],[文档编码]],Log[],MATCH(Log[[#Headers],[版本]],Log[#Headers],0),0),"") | D16: {=IF(IFERROR(MATCH(List[[#This Row],[文档编码]],Log[文档编码],0),0),MIN(IF(Log[文档编码]=List[[#This Row],[文档编码]],Log[日期])),"")} | E16: {=IF(IFERROR(MATCH(List[[#This Row],[文档编码]],Log[文档编码],0),FALSE),MAX(IF(Log[文档编码]=List[[#This Row],[文档编码]],Log[日期])),"")} | G16: 侧面开孔尺寸 / 位置 | H16: =HYPERLINK($H$1&List[[#This Row],[文档编码]]) -> .\24001A-ST-DW-0140
A17: =$F$1&"-ST-DW-0150" -> 24001A-ST-DW-0150 | B17: 箱体 - 前端装配图 | C17: =IFERROR(VLOOKUP(List[[#This Row],[末版受控]]&List[[#This Row],[文档编码]],Log[],MATCH(Log[[#Headers],[版本]],Log[#Headers],0),0),"") | D17: {=IF(IFERROR(MATCH(List[[#This Row],[文档编码]],Log[文档编码],0),0),MIN(IF(Log[文档编码]=List[[#This Row],[文档编码]],Log[日期])),"")} | E17: {=IF(IFERROR(MATCH(List[[#This Row],[文档编码]],Log[文档编码],0),FALSE),MAX(IF(Log[文档编码]=List[[#This Row],[文档编码]],Log[日期])),"")} | G17: 短边，取人员工作入口为前端 | H17: =HYPERLINK($H$1&List[[#This Row],[文档编码]]) -> .\24001A-ST-DW-0150
A18: =$F$1&"-ST-DW-0160" -> 24001A-ST-DW-0160 | B18: 箱体 - 后端装配图 | C18: =IFERROR(VLOOKUP(List[[#This Row],[末版受控]]&List[[#This Row],[文档编码]],Log[],MATCH(Log[[#Headers],[版本]],Log[#Headers],0),0),"") | D18: {=IF(IFERROR(MATCH(List[[#This Row],[文档编码]],Log[文档编码],0),0),MIN(IF(Log[文档编码]=List[[#This Row],[文档编码]],Log[日期])),"")} | E18: {=IF(IFERROR(MATCH(List[[#This Row],[文档编码]],Log[文档编码],0),FALSE),MAX(IF(Log[文档编码]=List[[#This Row],[文档编码]],Log[日期])),"")} | G18: 短边，取进货口 / 设备间操作端为后端 | H18: =HYPERLINK($H$1&List[[#This Row],[文档编码]]) -> .\24001A-ST-DW-0160
A19: =$F$1&"-ST-DW-0170" -> 24001A-ST-DW-0170 | B19: 箱体 - 隔墙装配图 | C19: =IFERROR(VLOOKUP(List[[#This Row],[末版受控]]&List[[#This Row],[文档编码]],Log[],MATCH(Log[[#Headers],[版本]],Log[#Headers],0),0),"") | D19: {=IF(IFERROR(MATCH(List[[#This Row],[文档编码]],Log[文档编码],0),0),MIN(IF(Log[文档编码]=List[[#This Row],[文档编码]],Log[日期])),"")} | E19: {=IF(IFERROR(MATCH(List[[#This Row],[文档编码]],Log[文档编码],0),FALSE),MAX(IF(Log[文档编码]=List[[#This Row],[文档编码]],Log[日期])),"")} | H19: =HYPERLINK($H$1&List[[#This Row],[文档编码]]) -> .\24001A-ST-DW-0170
A20: =$F$1&"-ST-DW-0180" -> 24001A-ST-DW-0180 | B20: 箱体 - 预埋布局图 | C20: =IFERROR(VLOOKUP(List[[#This Row],[末版受控]]&List[[#This Row],[文档编码]],Log[],MATCH(Log[[#Headers],[版本]],Log[#Headers],0),0),"") | D20: {=IF(IFERROR(MATCH(List[[#This Row],[文档编码]],Log[文档编码],0),0),MIN(IF(Log[文档编码]=List[[#This Row],[文档编码]],Log[日期])),"")} | E20: {=IF(IFERROR(MATCH(List[[#This Row],[文档编码]],Log[文档编码],0),FALSE),MAX(IF(Log[文档编码]=List[[#This Row],[文档编码]],Log[日期])),"")} | G20: 顶 / 墙 / 底预埋位置及尺寸 | H20: =HYPERLINK($H$1&List[[#This Row],[文档编码]]) -> .\24001A-ST-DW-0180
A21: =$F$1&"-ST-DW-0190" -> 24001A-ST-DW-0190 | B21: 箱体 - 其他布局图 | C21: =IFERROR(VLOOKUP(List[[#This Row],[末版受控]]&List[[#This Row],[文档编码]],Log[],MATCH(Log[[#Headers],[版本]],Log[#Headers],0),0),"") | D21: {=IF(IFERROR(MATCH(List[[#This Row],[文档编码]],Log[文档编码],0),0),MIN(IF(Log[文档编码]=List[[#This Row],[文档编码]],Log[日期])),"")} | E21: {=IF(IFERROR(MATCH(List[[#This Row],[文档编码]],Log[文档编码],0),FALSE),MAX(IF(Log[文档编码]=List[[#This Row],[文档编码]],Log[日期])),"")} | H21: =HYPERLINK($H$1&List[[#This Row],[文档编码]]) -> .\24001A-ST-DW-0190
A22: =$F$1&"-ST-DW-02XX" -> 24001A-ST-DW-02XX | B22: 门窗 XX - 装配图 | C22: =IFERROR(VLOOKUP(List[[#This Row],[末版受控]]&List[[#This Row],[文档编码]],Log[],MATCH(Log[[#Headers],[版本]],Log[#Headers],0),0),"") | D22: {=IF(IFERROR(MATCH(List[[#This Row],[文档编码]],Log[文档编码],0),0),MIN(IF(Log[文档编码]=List[[#This Row],[文档编码]],Log[日期])),"")} | E22: {=IF(IFERROR(MATCH(List[[#This Row],[文档编码]],Log[文档编码],0),FALSE),MAX(IF(Log[文档编码]=List[[#This Row],[文档编码]],Log[日期])),"")} | G22: 门窗装配图, XX 为编号, 默认从 01 递增（箱体工序安装） | H22: =HYPERLINK($H$1&List[[#This Row],[文档编码]]) -> .\24001A-ST-DW-02XX
A23: =$F$1&"-ST-DW-03XX" -> 24001A-ST-DW-03XX | B23: 围护 XX - 装配图 | C23: =IFERROR(VLOOKUP(List[[#This Row],[末版受控]]&List[[#This Row],[文档编码]],Log[],MATCH(Log[[#Headers],[版本]],Log[#Headers],0),0),"") | D23: {=IF(IFERROR(MATCH(List[[#This Row],[文档编码]],Log[文档编码],0),0),MIN(IF(Log[文档编码]=List[[#This Row],[文档编码]],Log[日期])),"")} | E23: {=IF(IFERROR(MATCH(List[[#This Row],[文档编码]],Log[文档编码],0),FALSE),MAX(IF(Log[文档编码]=List[[#This Row],[文档编码]],Log[日期])),"")} | G23: 围护装配图, XX 为编号, 默认从 01 递增 | H23: =HYPERLINK($H$1&List[[#This Row],[文档编码]]) -> .\24001A-ST-DW-03XX
A24: =$F$1&"-ST-DW-04XX" -> 24001A-ST-DW-04XX | B24: 吊具 XX - 装配图 | C24: =IFERROR(VLOOKUP(List[[#This Row],[末版受控]]&List[[#This Row],[文档编码]],Log[],MATCH(Log[[#Headers],[版本]],Log[#Headers],0),0),"") | D24: {=IF(IFERROR(MATCH(List[[#This Row],[文档编码]],Log[文档编码],0),0),MIN(IF(Log[文档编码]=List[[#This Row],[文档编码]],Log[日期])),"")} | E24: {=IF(IFERROR(MATCH(List[[#This Row],[文档编码]],Log[文档编码],0),FALSE),MAX(IF(Log[文档编码]=List[[#This Row],[文档编码]],Log[日期])),"")} | G24: 吊具装配图, XX 为编号, 默认从 01 递增 | H24: =HYPERLINK($H$1&List[[#This Row],[文档编码]]) -> .\24001A-ST-DW-04XX
A25: =$F$1&"-ST-DW-99XX" -> 24001A-ST-DW-99XX | B25: 其他配件 XX | C25: =IFERROR(VLOOKUP(List[[#This Row],[末版受控]]&List[[#This Row],[文档编码]],Log[],MATCH(Log[[#Headers],[版本]],Log[#Headers],0),0),"") | D25: {=IF(IFERROR(MATCH(List[[#This Row],[文档编码]],Log[文档编码],0),0),MIN(IF(Log[文档编码]=List[[#This Row],[文档编码]],Log[日期])),"")} | E25: {=IF(IFERROR(MATCH(List[[#This Row],[文档编码]],Log[文档编码],0),FALSE),MAX(IF(Log[文档编码]=List[[#This Row],[文档编码]],Log[日期])),"")} | G25: 其他配件 / 钣金图纸, 文件标题更换为配件名 | H25: =HYPERLINK($H$1&List[[#This Row],[文档编码]]) -> .\24001A-ST-DW-99XX
A26: =$F$1&"-ST-LS-0001" -> 24001A-ST-LS-0001 | B26: 结构 BOM | C26: =IFERROR(VLOOKUP(List[[#This Row],[末版受控]]&List[[#This Row],[文档编码]],Log[],MATCH(Log[[#Headers],[版本]],Log[#Headers],0),0),"") | D26: {=IF(IFERROR(MATCH(List[[#This Row],[文档编码]],Log[文档编码],0),0),MIN(IF(Log[文档编码]=List[[#This Row],[文档编码]],Log[日期])),"")} | E26: {=IF(IFERROR(MATCH(List[[#This Row],[文档编码]],Log[文档编码],0),FALSE),MAX(IF(Log[文档编码]=List[[#This Row],[文档编码]],Log[日期])),"")} | H26: =HYPERLINK($H$1&List[[#This Row],[文档编码]]) -> .\24001A-ST-LS-0001
A27: =$F$1&"-ST-LS-0002" -> 24001A-ST-LS-0002 | B27: 结构套料表 | C27: =IFERROR(VLOOKUP(List[[#This Row],[末版受控]]&List[[#This Row],[文档编码]],Log[],MATCH(Log[[#Headers],[版本]],Log[#Headers],0),0),"") | D27: {=IF(IFERROR(MATCH(List[[#This Row],[文档编码]],Log[文档编码],0),0),MIN(IF(Log[文档编码]=List[[#This Row],[文档编码]],Log[日期])),"")} | E27: {=IF(IFERROR(MATCH(List[[#This Row],[文档编码]],Log[文档编码],0),FALSE),MAX(IF(Log[文档编码]=List[[#This Row],[文档编码]],Log[日期])),"")} | H27: =HYPERLINK($H$1&List[[#This Row],[文档编码]]) -> .\24001A-ST-LS-0002
B28: 集成生产设计 | C28: =IFERROR(VLOOKUP(List[[#This Row],[末版受控]]&List[[#This Row],[文档编码]],Log[],MATCH(Log[[#Headers],[版本]],Log[#Headers],0),0),"") -> 0 | D28: {=IF(IFERROR(MATCH(List[[#This Row],[文档编码]],Log[文档编码],0),0),MIN(IF(Log[文档编码]=List[[#This Row],[文档编码]],Log[日期])),"")} | E28: {=IF(IFERROR(MATCH(List[[#This Row],[文档编码]],Log[文档编码],0),FALSE),MAX(IF(Log[文档编码]=List[[#This Row],[文档编码]],Log[日期])),"")} | H28: =HYPERLINK($H$1&List[[#This Row],[文档编码]]) -> .\
A29: =$F$1&"-AR-DW-0001" -> 24001A-AR-DW-0001 | B29: 集成总图 | C29: =IFERROR(VLOOKUP(List[[#This Row],[末版受控]]&List[[#This Row],[文档编码]],Log[],MATCH(Log[[#Headers],[版本]],Log[#Headers],0),0),"") | D29: {=IF(IFERROR(MATCH(List[[#This Row],[文档编码]],Log[文档编码],0),0),MIN(IF(Log[文档编码]=List[[#This Row],[文档编码]],Log[日期])),"")} | E29: {=IF(IFERROR(MATCH(List[[#This Row],[文档编码]],Log[文档编码],0),FALSE),MAX(IF(Log[文档编码]=List[[#This Row],[文档编码]],Log[日期])),"")} | G29: 箱体 & 集成完成后的总图. 在产品总图上细化 | H29: =HYPERLINK($H$1&List[[#This Row],[文档编码]]) -> .\24001A-AR-DW-0001
A30: =$F$1&"-AR-DW-0002" -> 24001A-AR-DW-0002 | B30: 保温 / 内饰面布局图 | C30: =IFERROR(VLOOKUP(List[[#This Row],[末版受控]]&List[[#This Row],[文档编码]],Log[],MATCH(Log[[#Headers],[版本]],Log[#Headers],0),0),"") | D30: {=IF(IFERROR(MATCH(List[[#This Row],[文档编码]],Log[文档编码],0),0),MIN(IF(Log[文档编码]=List[[#This Row],[文档编码]],Log[日期])),"")} | E30: {=IF(IFERROR(MATCH(List[[#This Row],[文档编码]],Log[文档编码],0),FALSE),MAX(IF(Log[文档编码]=List[[#This Row],[文档编码]],Log[日期])),"")} | G30: 保温层 / 内饰面 / 吊顶 / 抬高地板布局及安装工艺 | H30: =HYPERLINK($H$1&List[[#This Row],[文档编码]]) -> .\24001A-AR-DW-0002
A31: =$F$1&"-AR-DW-0003" -> 24001A-AR-DW-0003 | B31: 设备 / 家具布局图 | C31: =IFERROR(VLOOKUP(List[[#This Row],[末版受控]]&List[[#This Row],[文档编码]],Log[],MATCH(Log[[#Headers],[版本]],Log[#Headers],0),0),"") | D31: {=IF(IFERROR(MATCH(List[[#This Row],[文档编码]],Log[文档编码],0),0),MIN(IF(Log[文档编码]=List[[#This Row],[文档编码]],Log[日期])),"")} | E31: {=IF(IFERROR(MATCH(List[[#This Row],[文档编码]],Log[文档编码],0),FALSE),MAX(IF(Log[文档编码]=List[[#This Row],[文档编码]],Log[日期])),"")} | G31: 设备 / 家具安装的布局及安装工艺 | H31: =HYPERLINK($H$1&List[[#This Row],[文档编码]]) -> .\24001A-AR-DW-0003
A32: =$F$1&"-AR-DW-0004" -> 24001A-AR-DW-0004 | B32: 门窗布局图 | C32: =IFERROR(VLOOKUP(List[[#This Row],[末版受控]]&List[[#This Row],[文档编码]],Log[],MATCH(Log[[#Headers],[版本]],Log[#Headers],0),0),"") | D32: {=IF(IFERROR(MATCH(List[[#This Row],[文档编码]],Log[文档编码],0),0),MIN(IF(Log[文档编码]=List[[#This Row],[文档编码]],Log[日期])),"")} | E32: {=IF(IFERROR(MATCH(List[[#This Row],[文档编码]],Log[文档编码],0),FALSE),MAX(IF(Log[文档编码]=List[[#This Row],[文档编码]],Log[日期])),"")} | G32: 门窗位置及安装工艺（集成工序安装） | H32: =HYPERLINK($H$1&List[[#This Row],[文档编码]]) -> .\24001A-AR-DW-0004
A33: =$F$1&"-AR-DW-0008" -> 24001A-AR-DW-0008 | B33: 集成标贴图 | C33: =IFERROR(VLOOKUP(List[[#This Row],[末版受控]]&List[[#This Row],[文档编码]],Log[],MATCH(Log[[#Headers],[版本]],Log[#Headers],0),0),"") | D33: {=IF(IFERROR(MATCH(List[[#This Row],[文档编码]],Log[文档编码],0),0),MIN(IF(Log[文档编码]=List[[#This Row],[文档编码]],Log[日期])),"")} | E33: {=IF(IFERROR(MATCH(List[[#This Row],[文档编码]],Log[文档编码],0),FALSE),MAX(IF(Log[文档编码]=List[[#This Row],[文档编码]],Log[日期])),"")} | G33: 设备标贴 / 门窗开关标识等 | H33: =HYPERLINK($H$1&List[[#This Row],[文档编码]]) -> .\24001A-AR-DW-0008
A34: =$F$1&"-AR-LS-0001" -> 24001A-AR-LS-0001 | B34: 集成 BOM | C34: =IFERROR(VLOOKUP(List[[#This Row],[末版受控]]&List[[#This Row],[文档编码]],Log[],MATCH(Log[[#Headers],[版本]],Log[#Headers],0),0),"") | D34: {=IF(IFERROR(MATCH(List[[#This Row],[文档编码]],Log[文档编码],0),0),MIN(IF(Log[文档编码]=List[[#This Row],[文档编码]],Log[日期])),"")} | E34: {=IF(IFERROR(MATCH(List[[#This Row],[文档编码]],Log[文档编码],0),FALSE),MAX(IF(Log[文档编码]=List[[#This Row],[文档编码]],Log[日期])),"")} | H34: =HYPERLINK($H$1&List[[#This Row],[文档编码]]) -> .\24001A-AR-LS-0001
A35: =$F$1&"-EL-DW-0001" -> 24001A-EL-DW-0001 | B35: 强电原理图 | C35: =IFERROR(VLOOKUP(List[[#This Row],[末版受控]]&List[[#This Row],[文档编码]],Log[],MATCH(Log[[#Headers],[版本]],Log[#Headers],0),0),"") | D35: {=IF(IFERROR(MATCH(List[[#This Row],[文档编码]],Log[文档编码],0),0),MIN(IF(Log[文档编码]=List[[#This Row],[文档编码]],Log[日期])),"")} | E35: {=IF(IFERROR(MATCH(List[[#This Row],[文档编码]],Log[文档编码],0),FALSE),MAX(IF(Log[文档编码]=List[[#This Row],[文档编码]],Log[日期])),"")} | G35: 强电原理图 | H35: =HYPERLINK($H$1&List[[#This Row],[文档编码]]) -> .\24001A-EL-DW-0001
A36: =$F$1&"-EL-DW-0002" -> 24001A-EL-DW-0002 | B36: 弱电原理图 | C36: =IFERROR(VLOOKUP(List[[#This Row],[末版受控]]&List[[#This Row],[文档编码]],Log[],MATCH(Log[[#Headers],[版本]],Log[#Headers],0),0),"") | D36: {=IF(IFERROR(MATCH(List[[#This Row],[文档编码]],Log[文档编码],0),0),MIN(IF(Log[文档编码]=List[[#This Row],[文档编码]],Log[日期])),"")} | E36: {=IF(IFERROR(MATCH(List[[#This Row],[文档编码]],Log[文档编码],0),FALSE),MAX(IF(Log[文档编码]=List[[#This Row],[文档编码]],Log[日期])),"")} | G36: 弱电原理图 | H36: =HYPERLINK($H$1&List[[#This Row],[文档编码]]) -> .\24001A-EL-DW-0002
A37: =$F$1&"-EL-DW-0004" -> 24001A-EL-DW-0004 | B37: 强电布局图 | C37: =IFERROR(VLOOKUP(List[[#This Row],[末版受控]]&List[[#This Row],[文档编码]],Log[],MATCH(Log[[#Headers],[版本]],Log[#Headers],0),0),"") | D37: {=IF(IFERROR(MATCH(List[[#This Row],[文档编码]],Log[文档编码],0),0),MIN(IF(Log[文档编码]=List[[#This Row],[文档编码]],Log[日期])),"")} | E37: {=IF(IFERROR(MATCH(List[[#This Row],[文档编码]],Log[文档编码],0),FALSE),MAX(IF(Log[文档编码]=List[[#This Row],[文档编码]],Log[日期])),"")} | G37: 强电柜 / 照明 / 插座 / 开关等布局图 | H37: =HYPERLINK($H$1&List[[#This Row],[文档编码]]) -> .\24001A-EL-DW-0004
A38: =$F$1&"-EL-DW-0005" -> 24001A-EL-DW-0005 | B38: 弱电布局图 | C38: =IFERROR(VLOOKUP(List[[#This Row],[末版受控]]&List[[#This Row],[文档编码]],Log[],MATCH(Log[[#Headers],[版本]],Log[#Headers],0),0),"") | D38: {=IF(IFERROR(MATCH(List[[#This Row],[文档编码]],Log[文档编码],0),0),MIN(IF(Log[文档编码]=List[[#This Row],[文档编码]],Log[日期])),"")} | E38: {=IF(IFERROR(MATCH(List[[#This Row],[文档编码]],Log[文档编码],0),FALSE),MAX(IF(Log[文档编码]=List[[#This Row],[文档编码]],Log[日期])),"")} | G38: 弱电柜 / 网口 / 门禁 / 探头 / 摄像头等布局图 | H38: =HYPERLINK($H$1&List[[#This Row],[文档编码]]) -> .\24001A-EL-DW-0005
A39: =$F$1&"-EL-DW-0006" -> 24001A-EL-DW-0006 | B39: 桥架 / 线槽 / 线管布局图 | C39: =IFERROR(VLOOKUP(List[[#This Row],[末版受控]]&List[[#This Row],[文档编码]],Log[],MATCH(Log[[#Headers],[版本]],Log[#Headers],0),0),"") | D39: {=IF(IFERROR(MATCH(List[[#This Row],[文档编码]],Log[文档编码],0),0),MIN(IF(Log[文档编码]=List[[#This Row],[文档编码]],Log[日期])),"")} | E39: {=IF(IFERROR(MATCH(List[[#This Row],[文档编码]],Log[文档编码],0),FALSE),MAX(IF(Log[文档编码]=List[[#This Row],[文档编码]],Log[日期])),"")} | H39: =HYPERLINK($H$1&List[[#This Row],[文档编码]]) -> .\24001A-EL-DW-0006
A40: =$F$1&"-EL-DW-0008" -> 24001A-EL-DW-0008 | B40: 电气标贴图 | C40: =IFERROR(VLOOKUP(List[[#This Row],[末版受控]]&List[[#This Row],[文档编码]],Log[],MATCH(Log[[#Headers],[版本]],Log[#Headers],0),0),"") | D40: {=IF(IFERROR(MATCH(List[[#This Row],[文档编码]],Log[文档编码],0),0),MIN(IF(Log[文档编码]=List[[#This Row],[文档编码]],Log[日期])),"")} | E40: {=IF(IFERROR(MATCH(List[[#This Row],[文档编码]],Log[文档编码],0),FALSE),MAX(IF(Log[文档编码]=List[[#This Row],[文档编码]],Log[日期])),"")} | G40: 电缆标签 / 照明 / 插座等 | H40: =HYPERLINK($H$1&List[[#This Row],[文档编码]]) -> .\24001A-EL-DW-0008
...

Sheet Log
A1: C1 | B1: C2 | C1: 日期 | D1: 文档编码 | E1: 版本 | F1: 文档标题 | G1: 完整文件名 | H1: 链接 | I1: 创建文件夹 | J1: 复制文件
A2: =Log[[#This Row],[日期]]&Log[[#This Row],[文档编码]] | B2: =Log[[#This Row],[文档编码]]&Log[[#This Row],[版本]] | F2: =IFERROR(VLOOKUP(Log[[#This Row],[文档编码]],List[],2,0),"") | G2: =Log[[#This Row],[文档编码]]&"_"&Log[[#This Row],[版本]]&" "&Log[[#This Row],[文档标题]] -> _ | H2: =HYPERLINK(List!$H$2&TEXT(Log[[#This Row],[日期]],"YYYYMMDD")&" "&".zip") -> .\!log\19000100 .zip | I2: ="md "&Log[[#This Row],[文档编码]]&"\"&Log[[#This Row],[版本]] -> md \ | J2: ="move *"&Log[[#This Row],[文档编码]]&"* "&Log[[#This Row],[文档编码]]&"\"&Log[[#This Row],[版本]] -> move ** \
A3: =Log[[#This Row],[日期]]&Log[[#This Row],[文档编码]] | B3: =Log[[#This Row],[文档编码]]&Log[[#This Row],[版本]] | F3: =IFERROR(VLOOKUP(Log[[#This Row],[文档编码]],List[],2,0),"") | G3: =Log[[#This Row],[文档编码]]&"_"&Log[[#This Row],[版本]]&" "&Log[[#This Row],[文档标题]] -> _ | H3: =HYPERLINK(List!$H$2&TEXT(Log[[#This Row],[日期]],"YYYYMMDD")&" "&".zip") -> .\!log\19000100 .zip | I3: ="md "&Log[[#This Row],[文档编码]]&"\"&Log[[#This Row],[版本]] -> md \ | J3: ="move *"&Log[[#This Row],[文档编码]]&"* "&Log[[#This Row],[文档编码]]&"\"&Log[[#This Row],[版本]] -> move ** \
A4: =Log[[#This Row],[日期]]&Log[[#This Row],[文档编码]] | B4: =Log[[#This Row],[文档编码]]&Log[[#This Row],[版本]] | F4: =IFERROR(VLOOKUP(Log[[#This Row],[文档编码]],List[],2,0),"") | G4: =Log[[#This Row],[文档编码]]&"_"&Log[[#This Row],[版本]]&" "&Log[[#This Row],[文档标题]] -> _ | H4: =HYPERLINK(List!$H$2&TEXT(Log[[#This Row],[日期]],"YYYYMMDD")&" "&".zip") -> .\!log\19000100 .zip | I4: ="md "&Log[[#This Row],[文档编码]]&"\"&Log[[#This Row],[版本]] -> md \ | J4: ="move *"&Log[[#This Row],[文档编码]]&"* "&Log[[#This Row],[文档编码]]&"\"&Log[[#This Row],[版本]] -> move ** \
A5: =Log[[#This Row],[日期]]&Log[[#This Row],[文档编码]] | B5: =Log[[#This Row],[文档编码]]&Log[[#This Row],[版本]] | F5: =IFERROR(VLOOKUP(Log[[#This Row],[文档编码]],List[],2,0),"") | G5: =Log[[#This Row],[文档编码]]&"_"&Log[[#This Row],[版本]]&" "&Log[[#This Row],[文档标题]] -> _ | H5: =HYPERLINK(List!$H$2&TEXT(Log[[#This Row],[日期]],"YYYYMMDD")&" "&".zip") -> .\!log\19000100 .zip | I5: ="md "&Log[[#This Row],[文档编码]]&"\"&Log[[#This Row],[版本]] -> md \ | J5: ="move *"&Log[[#This Row],[文档编码]]&"* "&Log[[#This Row],[文档编码]]&"\"&Log[[#This Row],[版本]] -> move ** \
A6: =Log[[#This Row],[日期]]&Log[[#This Row],[文档编码]] | B6: =Log[[#This Row],[文档编码]]&Log[[#This Row],[版本]] | F6: =IFERROR(VLOOKUP(Log[[#This Row],[文档编码]],List[],2,0),"") | G6: =Log[[#This Row],[文档编码]]&"_"&Log[[#This Row],[版本]]&" "&Log[[#This Row],[文档标题]] -> _ | H6: =HYPERLINK(List!$H$2&TEXT(Log[[#This Row],[日期]],"YYYYMMDD")&" "&".zip") -> .\!log\19000100 .zip | I6: ="md "&Log[[#This Row],[文档编码]]&"\"&Log[[#This Row],[版本]] -> md \ | J6: ="move *"&Log[[#This Row],[文档编码]]&"* "&Log[[#This Row],[文档编码]]&"\"&Log[[#This Row],[版本]] -> move ** \
A7: =Log[[#This Row],[日期]]&Log[[#This Row],[文档编码]] | B7: =Log[[#This Row],[文档编码]]&Log[[#This Row],[版本]] | F7: =IFERROR(VLOOKUP(Log[[#This Row],[文档编码]],List[],2,0),"") | G7: =Log[[#This Row],[文档编码]]&"_"&Log[[#This Row],[版本]]&" "&Log[[#This Row],[文档标题]] -> _ | H7: =HYPERLINK(List!$H$2&TEXT(Log[[#This Row],[日期]],"YYYYMMDD")&" "&".zip") -> .\!log\19000100 .zip | I7: ="md "&Log[[#This Row],[文档编码]]&"\"&Log[[#This Row],[版本]] -> md \ | J7: ="move *"&Log[[#This Row],[文档编码]]&"* "&Log[[#This Row],[文档编码]]&"\"&Log[[#This Row],[版本]] -> move ** \
A8: =Log[[#This Row],[日期]]&Log[[#This Row],[文档编码]] | B8: =Log[[#This Row],[文档编码]]&Log[[#This Row],[版本]] | F8: =IFERROR(VLOOKUP(Log[[#This Row],[文档编码]],List[],2,0),"") | G8: =Log[[#This Row],[文档编码]]&"_"&Log[[#This Row],[版本]]&" "&Log[[#This Row],[文档标题]] -> _ | H8: =HYPERLINK(List!$H$2&TEXT(Log[[#This Row],[日期]],"YYYYMMDD")&" "&".zip") -> .\!log\19000100 .zip | I8: ="md "&Log[[#This Row],[文档编码]]&"\"&Log[[#This Row],[版本]] -> md \ | J8: ="move *"&Log[[#This Row],[文档编码]]&"* "&Log[[#This Row],[文档编码]]&"\"&Log[[#This Row],[版本]] -> move ** \
A9: =Log[[#This Row],[日期]]&Log[[#This Row],[文档编码]] | B9: =Log[[#This Row],[文档编码]]&Log[[#This Row],[版本]] | F9: =IFERROR(VLOOKUP(Log[[#This Row],[文档编码]],List[],2,0),"") | G9: =Log[[#This Row],[文档编码]]&"_"&Log[[#This Row],[版本]]&" "&Log[[#This Row],[文档标题]] -> _ | H9: =HYPERLINK(List!$H$2&TEXT(Log[[#This Row],[日期]],"YYYYMMDD")&" "&".zip") -> .\!log\19000100 .zip | I9: ="md "&Log[[#This Row],[文档编码]]&"\"&Log[[#This Row],[版本]] -> md \ | J9: ="move *"&Log[[#This Row],[文档编码]]&"* "&Log[[#This Row],[文档编码]]&"\"&Log[[#This Row],[版本]] -> move ** \
A10: =Log[[#This Row],[日期]]&Log[[#This Row],[文档编码]] | B10: =Log[[#This Row],[文档编码]]&Log[[#This Row],[版本]] | F10: =IFERROR(VLOOKUP(Log[[#This Row],[文档编码]],List[],2,0),"") | G10: =Log[[#This Row],[文档编码]]&"_"&Log[[#This Row],[版本]]&" "&Log[[#This Row],[文档标题]] -> _ | H10: =HYPERLINK(List!$H$2&TEXT(Log[[#This Row],[日期]],"YYYYMMDD")&" "&".zip") -> .\!log\19000100 .zip | I10: ="md "&Log[[#This Row],[文档编码]]&"\"&Log[[#This Row],[版本]] -> md \ | J10: ="move *"&Log[[#This Row],[文档编码]]&"* "&Log[[#This Row],[文档编码]]&"\"&Log[[#This Row],[版本]] -> move ** \
A11: =Log[[#This Row],[日期]]&Log[[#This Row],[文档编码]] | B11: =Log[[#This Row],[文档编码]]&Log[[#This Row],[版本]] | F11: =IFERROR(VLOOKUP(Log[[#This Row],[文档编码]],List[],2,0),"") | G11: =Log[[#This Row],[文档编码]]&"_"&Log[[#This Row],[版本]]&" "&Log[[#This Row],[文档标题]] -> _ | H11: =HYPERLINK(List!$H$2&TEXT(Log[[#This Row],[日期]],"YYYYMMDD")&" "&".zip") -> .\!log\19000100 .zip | I11: ="md "&Log[[#This Row],[文档编码]]&"\"&Log[[#This Row],[版本]] -> md \ | J11: ="move *"&Log[[#This Row],[文档编码]]&"* "&Log[[#This Row],[文档编码]]&"\"&Log[[#This Row],[版本]] -> move ** \
A12: =Log[[#This Row],[日期]]&Log[[#This Row],[文档编码]] | B12: =Log[[#This Row],[文档编码]]&Log[[#This Row],[版本]] | F12: =IFERROR(VLOOKUP(Log[[#This Row],[文档编码]],List[],2,0),"") | G12: =Log[[#This Row],[文档编码]]&"_"&Log[[#This Row],[版本]]&" "&Log[[#This Row],[文档标题]] -> _ | H12: =HYPERLINK(List!$H$2&TEXT(Log[[#This Row],[日期]],"YYYYMMDD")&" "&".zip") -> .\!log\19000100 .zip | I12: ="md "&Log[[#This Row],[文档编码]]&"\"&Log[[#This Row],[版本]] -> md \ | J12: ="move *"&Log[[#This Row],[文档编码]]&"* "&Log[[#This Row],[文档编码]]&"\"&Log[[#This Row],[版本]] -> move ** \
A13: =Log[[#This Row],[日期]]&Log[[#This Row],[文档编码]] | B13: =Log[[#This Row],[文档编码]]&Log[[#This Row],[版本]] | F13: =IFERROR(VLOOKUP(Log[[#This Row],[文档编码]],List[],2,0),"") | G13: =Log[[#This Row],[文档编码]]&"_"&Log[[#This Row],[版本]]&" "&Log[[#This Row],[文档标题]] -> _ | H13: =HYPERLINK(List!$H$2&TEXT(Log[[#This Row],[日期]],"YYYYMMDD")&" "&".zip") -> .\!log\19000100 .zip | I13: ="md "&Log[[#This Row],[文档编码]]&"\"&Log[[#This Row],[版本]] -> md \ | J13: ="move *"&Log[[#This Row],[文档编码]]&"* "&Log[[#This Row],[文档编码]]&"\"&Log[[#This Row],[版本]] -> move ** \
... A25: =Log[[#This Row],[日期]]&Log[[#This Row],[文档编码]] | B25: =Log[[#This Row],[文档编码]]&Log[[#This Row],[版本]] | F25: =IFERROR(VLOOKUP(Log[[#This Row],[文档编码]],List[],2,0),"") | G25: =Log[[#This Row],[文档编码]]&"_"&Log[[#This Row],[版本]]&" "&Log[[#This Row],[文档标题]] -> _ | H25: =HYPERLINK(List!$H$2&TEXT(Log[[#This Row],[日期]],"YYYYMMDD")&" "&".zip") -> .\!log\19000100 .zip | I25: ="md "&Log[[#This Row],[文档编码]]&"\"&Log[[#This Row],[版本]] -> md \ | J25: ="move *"&Log[[#This Row],[文档编码]]&"* "&Log[[#This Row],[文档编码]]&"\"&Log[[#This Row],[版本]] -> move ** \
